Workbook

Sheet CONCILIAÇÃO FINANCEIRA - GECOV
B3: CONCILIAÇÃO FINANCEIRA - GECOV
B5: MOVIMENTAÇÃO FINANCEIRA
B6: Convênio:
B7: Convenente:
B8: Vigência:
B9: CC:
B10: Data | C10: Item | D10: Entrada | E10: Saída | F10: Saldo | G10: Aplicação | H10: Resgate | I10: Rendimentos | J10: Tarifa Paga | K10: Tarifa Devolvida | L10: Saldo de tarifa
D11: 0 | E11: 0 | F11: =D11-E11 -> 0 | G11: =IF($G$10=C11,E11,"-") -> - | H11: =IF($H$10=C11,D11,"-") -> - | J11: =IF("Tarifa"=C11,E11,"-") -> - | K11: =IF("Tarifa"=C11,D11,"-") -> -
D12: 0 | E12: 0 | F12: =F11+D12-E12 -> 0 | G12: =IF($G$10=C12,E12,"-") -> - | H12: =IF($H$10=C12,D12,"-") -> - | J12: =IF("Tarifa"=C12,E12,"-") -> - | K12: =IF("Tarifa"=C12,D12,"-") -> -
D13: 0 | E13: 0 | F13: =F12+D13-E13 -> 0 | G13: =IF($G$10=C13,E13,"-") -> - | H13: =IF($H$10=C13,D13,"-") -> - | J13: =IF("Tarifa"=C13,E13,"-") -> - | K13: =IF("Tarifa"=C13,D13,"-") -> -
D14: 0 | E14: 0 | F14: =F13+D14-E14 -> 0 | G14: =IF($G$10=C14,E14,"-") -> - | H14: =IF($H$10=C14,D14,"-") -> - | J14: =IF("Tarifa"=C14,E14,"-") -> - | K14: =IF("Tarifa"=C14,D14,"-") -> -
D15: 0 | E15: 0 | F15: =F14+D15-E15 -> 0 | G15: =IF($G$10=C15,E15,"-") -> - | H15: =IF($H$10=C15,D15,"-") -> - | J15: =IF("Tarifa"=C15,E15,"-") -> - | K15: =IF("Tarifa"=C15,D15,"-") -> -
D16: 0 | E16: 0 | F16: =F15+D16-E16 -> 0 | G16: =IF($G$10=C16,E16,"-") -> - | H16: =IF($H$10=C16,D16,"-") -> - | J16: =IF("Tarifa"=C16,E16,"-") -> - | K16: =IF("Tarifa"=C16,D16,"-") -> -
D17: 0 | E17: 0 | F17: =F16+D17-E17 -> 0 | G17: =IF($G$10=C17,E17,"-") -> - | H17: =IF($H$10=C17,D17,"-") -> - | J17: =IF("Tarifa"=C17,E17,"-") -> - | K17: =IF("Tarifa"=C17,D17,"-") -> -
D18: 0 | E18: 0 | F18: =F17+D18-E18 -> 0 | G18: =IF($G$10=C18,E18,"-") -> - | H18: =IF($H$10=C18,D18,"-") -> - | J18: =IF("Tarifa"=C18,E18,"-") -> - | K18: =IF("Tarifa"=C18,D18,"-") -> -
D19: 0 | E19: 0 | F19: =F18+D19-E19 -> 0 | G19: =IF($G$10=C19,E19,"-") -> - | H19: =IF($H$10=C19,D19,"-") -> - | J19: =IF("Tarifa"=C19,E19,"-") -> - | K19: =IF("Tarifa"=C19,D19,"-") -> -
D20: 0 | E20: 0 | F20: =F19+D20-E20 -> 0 | G20: =IF($G$10=C20,E20,"-") -> - | H20: =IF($H$10=C20,D20,"-") -> - | J20: =IF("Tarifa"=C20,E20,"-") -> - | K20: =IF("Tarifa"=C20,D20,"-") -> -
D21: 0 | E21: 0 | F21: =F20+D21-E21 -> 0 | G21: =IF($G$10=C21,E21,"-") -> - | H21: =IF($H$10=C21,D21,"-") -> - | J21: =IF("Tarifa"=C21,E21,"-") -> - | K21: =IF("Tarifa"=C21,D21,"-") -> -
D22: 0 | E22: 0 | F22: =F21+D22-E22 -> 0 | G22: =IF($G$10=C22,E22,"-") -> - | H22: =IF($H$10=C22,D22,"-") -> - | J22: =IF("Tarifa"=C22,E22,"-") -> - | K22: =IF("Tarifa"=C22,D22,"-") -> -
D23: 0 | E23: 0 | F23: =F22+D23-E23 -> 0 | G23: =IF($G$10=C23,E23,"-") -> - | H23: =IF($H$10=C23,D23,"-") -> - | J23: =IF("Tarifa"=C23,E23,"-") -> - | K23: =IF("Tarifa"=C23,D23,"-") -> -
... D30: 0 | E30: 0 | F30: =F29+D30-E30 -> 0 | G30: =IF($G$10=C30,E30,"-") -> - | H30: =IF($H$10=C30,D30,"-") -> - | J30: =IF("Tarifa"=C30,E30,"-") -> - | K30: =IF("Tarifa"=C30,D30,"-") -> -
B31: TOTAL | D31: =SUM(D11:D30) -> 0 | E31: =SUM(E11:E30) -> 0 | F31: =F30+D31-E31 -> 0 | G31: =SUM(G11:G30) -> 0 | H31: =SUM(H11:H30) -> 0 | I31: =H31-G31 -> 0 | J31: =SUM(J11:J30) -> 0 | K31: =SUM(K11:K30) -> 0 | L31: =J31-K31 -> 0
B33: CONTRATO EMPRESA:
B34: NF FLS | C34: NE | D34: NF | E34: DATA | F34: VALOR BRUTO | G34: INSS | H34: IR | I34: ISS | J34: LÍQUIDO | K34: DATA PG | L34: ISS FLS | M34: INSS FLS
J35: =F35-G35-H35-I35 -> 0
J36: =F36-G36-H36-I36 -> 0
J37: =F37-G37-H37-I37 -> 0
J38: =F38-G38-H38-I38 -> 0
J39: =F39-G39-H39-I39 -> 0
J40: =F40-G40-H40-I40 -> 0
J41: =F41-G41-H41-I41 -> 0
B42: TOTAL | F42: =SUM(F35:F41) -> 0 | G42: =SUM(G35:G41) -> 0 | H42: =SUM(H35:H41) -> 0 | I42: =SUM(I35:I41) -> 0 | J42: =F42-G42-H42-I42 -> 0
C44: PREVISÃO PT | E44: % | F44: REPASSADO | G44: EXECUTADO | H44: SALDO REPASSE | I44: RENDIMENTO | J44: SALDO | M44: Dados básicos da correção pela Selic
C45: CONCEDENTE | E45: =D45/D47 -> #DIV/0! | G45: =G47*E45 -> #DIV/0! | H45: =F45-G45 -> #DIV/0! | I45: =I47*E45 -> #DIV/0! | J45: =F45+I45-G45 -> #DIV/0!
C46: CONVENENTE | E46: =D46/D47 -> #DIV/0! | G46: =G47*E46 -> #DIV/0! | H46: =F46-G46 -> #DIV/0! | I46: =I47*E46 -> #DIV/0! | J46: =F46+I46-G46 -> #DIV/0!
C47: TOTAL | D47: =SUM(D45:D46) -> 0 | E47: =SUM(E45:E46) -> #DIV/0! | F47: =SUM(F45:F46) -> 0 | G47: =F42 -> 0 | H47: =SUM(H45:H46) -> #DIV/0! | I47: =I31 -> 0 | J47: =SUM(J45:J46) -> #DIV/0!
B50: PROPORCIONALIDADE | C50: SALDO | D50: REND NÃO APLIC | E50: REND TARIFA | F50: NOTA TÉCNICA | G50: REND. NOTA TÉC | H50: ATRASO DEV. | I50: TOTAL | J50: SALDO DEVOLVIDO | K50: Dev. Maior/Menor
B51: CONCEDENTE - % | C51: =J45 -> #DIV/0! | D51: =D53*E45 -> #DIV/0! | E51: =E53*E45 -> #DIV/0! | F51: =F53*E45 -> #DIV/0! | G51: =G53*E45 -> #DIV/0! | H51: =H53*E45 -> #DIV/0! | I51: =SUM(B51:H51) -> #DIV/0! | K51: =I51-J51 -> #DIV/0!
B52: CONVENENTE - % | C52: =J46 -> #DIV/0! | D52: =D53*E46 -> #DIV/0! | E52: =E53*E46 -> #DIV/0! | F52: =F53*E46 -> #DIV/0! | G52: =G53*E46 -> #DIV/0! | H52: =H53*E46 -> #DIV/0! | I52: =SUM(B52:H52) -> #DIV/0!
B53: TOTAL | C53: =J47 -> #DIV/0! | D53: =L73 -> 0 | E53: =I94 -> 0 | F53: =F102 -> 0 | G53: =J102 -> 0 | H53: =D109 -> 0 | I53: =SUM(I51:I52) -> #DIV/0!
...

Sheet GECON
B3: Informações Financeiras do Convênio - GECON
B4: Convenente | C4: ='CONCILIAÇÃO FINANCEIRA - GECOV'!C8:E8 -> 0
B5: Nº do Convênio | C5: ='CONCILIAÇÃO FINANCEIRA - GECOV'!C6 -> 0
B6: Participantes | C6: Valor Repassado | D6: Participação % | E6: Despesa Realizada | F6: Rendimento | G6: Rendimento Selic | H6: Devolução realizada (I) | K6: Devolução devida em função da proporcionalidade dos recursos (II) | N6: Saldo a devolver/(receber) para o convenente (III) = (I) - (II) - (IV)
H7: Principal | I7: Rendimento | J7: Total | K7: Principal | L7: Rendimento | M7: Total | N7: Principal | O7: Rendimento | P7: Total
B8: MGI | C8: ='CONCILIAÇÃO FINANCEIRA - GECOV'!D45 -> 0 | D8: =C8/C10*100 -> #DIV/0! | E8: =E10*D8% -> #DIV/0! | F8: =F10*D8% -> #DIV/0! | G8: =E20 -> #DIV/0! | H8: =IF(J8*(C8-E8)/(C8-E8+F8+G8)>0,J8*(C8-E8)/(C8-E8+F8+G8),0) -> #DIV/0! | I8: =IF(C8>E8,J8*(F8+G8)/(C8-E8+F8+G8),E21) -> #DIV/0! | J8: =E21 -> 0 | K8: =IF(C8-E8>0,C8-E8,0) -> #DIV/0! | L8: =IF(C8>E8,F8+G8,F8+G8+C8-E8) -> #DIV/0! | M8: =K8+L8 -> #DIV/0! | N8: =H8-K8 -> #DIV/0! | O8: =I8-L8-E17-E18 -> #DIV/0! | P8: =J8-M8-E17-E18 -> #DIV/0!
B9: Municipio | C9: ='CONCILIAÇÃO FINANCEIRA - GECOV'!D46 -> 0 | D9: =C9/C10*100 -> #DIV/0! | E9: =E10*D9% -> #DIV/0! | F9: =F10*D9% -> #DIV/0! | G9: 0 | N9: =H9-K9 -> 0 | O9: =I9-L9 -> 0 | P9: =J9-M9 -> 0
B10: Total | C10: =C8+C9 -> 0 | D10: =D8+D9 -> #DIV/0! | E10: ='CONCILIAÇÃO FINANCEIRA - GECOV'!G47 -> 0 | F10: ='CONCILIAÇÃO FINANCEIRA - GECOV'!I31 -> 0 | G10: =G8+G9 -> #DIV/0! | H10: =H8+H9 -> #DIV/0! | I10: =I8+I9 -> #DIV/0! | J10: =J8+J9 -> 0 | K10: =K8+K9 -> #DIV/0! | L10: =L8+L9 -> #DIV/0! | M10: =K10+L10 -> #DIV/0! | N10: =H10-K10 -> #DIV/0! | O10: =I10-L10-E17-E18 -> #DIV/0! | P10: =J10-M10-E17-E18 -> #DIV/0!
B13: Informações Financeiras do Convênio
B14: Valor repassado ao convenente | E14: =C8 -> 0
B15: Contrapartida | E15: =C9 -> 0 | I15: Quadro I
B16: Despesa realizada | E16: ='CONCILIAÇÃO FINANCEIRA - GECOV'!F42 -> 0 | I16: Devolução realizada pelo Convenente | M16: =M20+M21 -> 0
B17: Despesa não autorizada (IV) | E17: ='CONCILIAÇÃO FINANCEIRA - GECOV'!F51 -> #DIV/0! | I17: DAE - recurso transferido para MGI
B18: Tarifas Bancarias Indevidas (IV)* | I18: DAE - recurso com EMG
B19: Rendimento do repasse | E19: ='CONCILIAÇÃO FINANCEIRA - GECOV'!I31 -> 0 | I19: Recurso Transferido direto para MGI | M19: =M20-M17-M18 -> 0
B20: Rendimento Selic | E20: ='CONCILIAÇÃO FINANCEIRA - GECOV'!D51+'CONCILIAÇÃO FINANCEIRA - GECOV'!E51+'CONCILIAÇÃO FINANCEIRA - GECOV'!G51+'CONCILIAÇÃO FINANCEIRA - GECOV'!H51+'CONCILIAÇÃO FINANCEIRA - GECOV'!G57+'CONCILIAÇÃO FINANCEIRA - GECOV'!G58 -> #DIV/0! | I20: ¬ Recurso Devolvido | M20: ='CONCILIAÇÃO FINANCEIRA - GECOV'!J51+'CONCILIAÇÃO FINANCEIRA - GECOV'!M51+'CONCILIAÇÃO FINANCEIRA - GECOV'!D57+'CONCILIAÇÃO FINANCEIRA - GECOV'!D58 -> 0
B21: Devolução Realizada pelo Convenente (Quadro I ) | E21: =M16 -> 0
B22: * apenas tarifas não estornadas ou não devolvidas à conta do Convênio
B24: Contabilizações
B25: Receita de rendimentos sobre aplicações na convenente | E25: =IF(E8>C8,F8+G8+C8-E8,F8+G8)+E18 -> #DIV/0!
B26: Baixa de Obrigações por Repasse | E26: =IF(C8>E8,E8,C8)-E17 -> #DIV/0! | I26: Preencher apenas as abas em amarelo
B27: Baixa Contábil - Redução do capital integralizado - mediante aprovação do CA (1) | E27: =IF(E26+K8=E14,E26+K8,C8) -> #DIV/0!
B28: (1)Repasse realizado - Parte Concedente
B31: Destinação dos recursos devolvidos
B32: MGI | E32: =L8+E18 -> #DIV/0! | S32: Valor Repassado | T32: =E14 -> 0
B33: Devolução ao Estado de MG | E33: =K8+E17 -> #DIV/0! | S33: Despesa Proporcional | T33: =E8 -> #DIV/0! | U33: =T32-T33 -> #DIV/0!
B34: Recursos remanescentes da transação - Devolução devida (II) | E34: =E32+E33 -> #DIV/0! | S34: Rendimento Proporcional | T34: =F8 -> #DIV/0! | U34: 2966.4
B35: Devolução recebida a maior - pgto para convenente (III) | E35: =IF(P8>0,P8,0) -> #DIV/0! | S35: Rendimento Selic | T35: =G8 -> #DIV/0!
B36: Devolução recebida a menor - receber do convenente (III) | E36: =IF(P8<0,-P10,0) -> #DIV/0! | S36: Despesa não autorizada | T36: =E17+E18 -> #DIV/0!
B37: Recursos remanescentes da transação - Devolução realizada (I) | E37: =E34+E35-E36 -> #DIV/0!
S38: Devolução | T38: =E21 -> 0
S40: Saldo a( Devolver) ou Receber | T40: =T32-T33+T34+T35-T38+T36 -> #DIV/0! | U40: =IF(-T40=P10,"OK","****erro****") -> #DIV/0!
